Workbook

Sheet Dashboard
B3: JONCTION — Suivi financier
B4: Année 2026 — remplissez Revenus & Dépenses, tout se calcule automatiquement ici.
B6: Chiffre d'affaires HT | D6: Charges HT | F6: Marge nette | H6: Marge %
B7: =SUM(Revenus!E2:E501) | D7: =D23 | F7: =B7-D7 | H7: =IF(B7=0,0,F7/B7)
B9: Suivi mensuel
B10: Mois | C10: CA | D10: Charges | E10: Marge | F10: Marge % | G10: MRR récurrent | H10: Charges récurrentes
B11: 46023 | C11: =SUMIFS(Revenus!$E$2:$E$501,Revenus!$G$2:$G$501,$B11) | D11: =SUMIFS('Dépenses'!$F$2:$F$499,'Dépenses'!$H$2:$H$499,"<="&$B11,'Dépenses'!$G$2:$G$499,"Oui")*($B11<=DATE(YEAR(TODAY()),MONTH(TODAY()),1))+SUMIFS('Dépenses'!$F$2:$F$499,'Dépenses'!$H$2:$H$499,$B11,'Dépenses'!$G$2:$G$499,"<>Oui")+SUMIFS('Charges fixes'!$D$2:$D$100,'Charges fixes'!$E$2:$E$100,"<="&$B11)*($B11<=DATE(YEAR(TODAY()),MONTH(TODAY()),1)) | E11: =C11-D11 | F11: =IF(C11=0,0,E11/C11) | G11: =SUMIFS(Revenus!$E$2:$E$501,Revenus!$G$2:$G$501,$B11,Revenus!$F$2:$F$501,"Oui") | H11: =SUMIFS('Dépenses'!$F$2:$F$499,'Dépenses'!$H$2:$H$499,"<="&$B11,'Dépenses'!$G$2:$G$499,"Oui")*($B11<=DATE(YEAR(TODAY()),MONTH(TODAY()),1))+SUMIFS('Charges fixes'!$D$2:$D$100,'Charges fixes'!$E$2:$E$100,"<="&$B11)*($B11<=DATE(YEAR(TODAY()),MONTH(TODAY()),1))
B12: 46054 | C12: =SUMIFS(Revenus!$E$2:$E$501,Revenus!$G$2:$G$501,$B12) | D12: =SUMIFS('Dépenses'!$F$2:$F$499,'Dépenses'!$H$2:$H$499,"<="&$B12,'Dépenses'!$G$2:$G$499,"Oui")*($B12<=DATE(YEAR(TODAY()),MONTH(TODAY()),1))+SUMIFS('Dépenses'!$F$2:$F$499,'Dépenses'!$H$2:$H$499,$B12,'Dépenses'!$G$2:$G$499,"<>Oui")+SUMIFS('Charges fixes'!$D$2:$D$100,'Charges fixes'!$E$2:$E$100,"<="&$B12)*($B12<=DATE(YEAR(TODAY()),MONTH(TODAY()),1)) | E12: =C12-D12 | F12: =IF(C12=0,0,E12/C12) | G12: =SUMIFS(Revenus!$E$2:$E$501,Revenus!$G$2:$G$501,$B12,Revenus!$F$2:$F$501,"Oui") | H12: =SUMIFS('Dépenses'!$F$2:$F$499,'Dépenses'!$H$2:$H$499,"<="&$B12,'Dépenses'!$G$2:$G$499,"Oui")*($B12<=DATE(YEAR(TODAY()),MONTH(TODAY()),1))+SUMIFS('Charges fixes'!$D$2:$D$100,'Charges fixes'!$E$2:$E$100,"<="&$B12)*($B12<=DATE(YEAR(TODAY()),MONTH(TODAY()),1))
B13: 46082 | C13: =SUMIFS(Revenus!$E$2:$E$501,Revenus!$G$2:$G$501,$B13) | D13: =SUMIFS('Dépenses'!$F$2:$F$499,'Dépenses'!$H$2:$H$499,"<="&$B13,'Dépenses'!$G$2:$G$499,"Oui")*($B13<=DATE(YEAR(TODAY()),MONTH(TODAY()),1))+SUMIFS('Dépenses'!$F$2:$F$499,'Dépenses'!$H$2:$H$499,$B13,'Dépenses'!$G$2:$G$499,"<>Oui")+SUMIFS('Charges fixes'!$D$2:$D$100,'Charges fixes'!$E$2:$E$100,"<="&$B13)*($B13<=DATE(YEAR(TODAY()),MONTH(TODAY()),1)) | E13: =C13-D13 | F13: =IF(C13=0,0,E13/C13) | G13: =SUMIFS(Revenus!$E$2:$E$501,Revenus!$G$2:$G$501,$B13,Revenus!$F$2:$F$501,"Oui") | H13: =SUMIFS('Dépenses'!$F$2:$F$499,'Dépenses'!$H$2:$H$499,"<="&$B13,'Dépenses'!$G$2:$G$499,"Oui")*($B13<=DATE(YEAR(TODAY()),MONTH(TODAY()),1))+SUMIFS('Charges fixes'!$D$2:$D$100,'Charges fixes'!$E$2:$E$100,"<="&$B13)*($B13<=DATE(YEAR(TODAY()),MONTH(TODAY()),1))
B14: 46113 | C14: =SUMIFS(Revenus!$E$2:$E$501,Revenus!$G$2:$G$501,$B14) | D14: =SUMIFS('Dépenses'!$F$2:$F$499,'Dépenses'!$H$2:$H$499,"<="&$B14,'Dépenses'!$G$2:$G$499,"Oui")*($B14<=DATE(YEAR(TODAY()),MONTH(TODAY()),1))+SUMIFS('Dépenses'!$F$2:$F$499,'Dépenses'!$H$2:$H$499,$B14,'Dépenses'!$G$2:$G$499,"<>Oui")+SUMIFS('Charges fixes'!$D$2:$D$100,'Charges fixes'!$E$2:$E$100,"<="&$B14)*($B14<=DATE(YEAR(TODAY()),MONTH(TODAY()),1)) | E14: =C14-D14 | F14: =IF(C14=0,0,E14/C14) | G14: =SUMIFS(Revenus!$E$2:$E$501,Revenus!$G$2:$G$501,$B14,Revenus!$F$2:$F$501,"Oui") | H14: =SUMIFS('Dépenses'!$F$2:$F$499,'Dépenses'!$H$2:$H$499,"<="&$B14,'Dépenses'!$G$2:$G$499,"Oui")*($B14<=DATE(YEAR(TODAY()),MONTH(TODAY()),1))+SUMIFS('Charges fixes'!$D$2:$D$100,'Charges fixes'!$E$2:$E$100,"<="&$B14)*($B14<=DATE(YEAR(TODAY()),MONTH(TODAY()),1))
B15: 46143 | C15: =SUMIFS(Revenus!$E$2:$E$501,Revenus!$G$2:$G$501,$B15) | D15: =SUMIFS('Dépenses'!$F$2:$F$499,'Dépenses'!$H$2:$H$499,"<="&$B15,'Dépenses'!$G$2:$G$499,"Oui")*($B15<=DATE(YEAR(TODAY()),MONTH(TODAY()),1))+SUMIFS('Dépenses'!$F$2:$F$499,'Dépenses'!$H$2:$H$499,$B15,'Dépenses'!$G$2:$G$499,"<>Oui")+SUMIFS('Charges fixes'!$D$2:$D$100,'Charges fixes'!$E$2:$E$100,"<="&$B15)*($B15<=DATE(YEAR(TODAY()),MONTH(TODAY()),1)) | E15: =C15-D15 | F15: =IF(C15=0,0,E15/C15) | G15: =SUMIFS(Revenus!$E$2:$E$501,Revenus!$G$2:$G$501,$B15,Revenus!$F$2:$F$501,"Oui") | H15: =SUMIFS('Dépenses'!$F$2:$F$499,'Dépenses'!$H$2:$H$499,"<="&$B15,'Dépenses'!$G$2:$G$499,"Oui")*($B15<=DATE(YEAR(TODAY()),MONTH(TODAY()),1))+SUMIFS('Charges fixes'!$D$2:$D$100,'Charges fixes'!$E$2:$E$100,"<="&$B15)*($B15<=DATE(YEAR(TODAY()),MONTH(TODAY()),1))
B16: 46174 | C16: =SUMIFS(Revenus!$E$2:$E$501,Revenus!$G$2:$G$501,$B16) | E16: =C16-D16 | F16: =IF(C16=0,0,E16/C16) | G16: =SUMIFS(Revenus!$E$2:$E$501,Revenus!$G$2:$G$501,$B16,Revenus!$F$2:$F$501,"Oui") | H16: =SUMIFS('Dépenses'!$F$2:$F$499,'Dépenses'!$H$2:$H$499,"<="&$B16,'Dépenses'!$G$2:$G$499,"Oui")*($B16<=DATE(YEAR(TODAY()),MONTH(TODAY()),1))+SUMIFS('Charges fixes'!$D$2:$D$100,'Charges fixes'!$E$2:$E$100,"<="&$B16)*($B16<=DATE(YEAR(TODAY()),MONTH(TODAY()),1))
B17: 46204 | C17: =SUMIFS(Revenus!$E$2:$E$501,Revenus!$G$2:$G$501,$B17) | D17: =SUMIFS('Dépenses'!$F$2:$F$499,'Dépenses'!$H$2:$H$499,"<="&$B17,'Dépenses'!$G$2:$G$499,"Oui")*($B17<=DATE(YEAR(TODAY()),MONTH(TODAY()),1))+SUMIFS('Dépenses'!$F$2:$F$499,'Dépenses'!$H$2:$H$499,$B17,'Dépenses'!$G$2:$G$499,"<>Oui")+SUMIFS('Charges fixes'!$D$2:$D$100,'Charges fixes'!$E$2:$E$100,"<="&$B17)*($B17<=DATE(YEAR(TODAY()),MONTH(TODAY()),1)) | E17: =C17-D17 | F17: =IF(C17=0,0,E17/C17) | G17: =SUMIFS(Revenus!$E$2:$E$501,Revenus!$G$2:$G$501,$B17,Revenus!$F$2:$F$501,"Oui") | H17: =SUMIFS('Dépenses'!$F$2:$F$499,'Dépenses'!$H$2:$H$499,"<="&$B17,'Dépenses'!$G$2:$G$499,"Oui")*($B17<=DATE(YEAR(TODAY()),MONTH(TODAY()),1))+SUMIFS('Charges fixes'!$D$2:$D$100,'Charges fixes'!$E$2:$E$100,"<="&$B17)*($B17<=DATE(YEAR(TODAY()),MONTH(TODAY()),1))
B18: 46235 | C18: =SUMIFS(Revenus!$E$2:$E$501,Revenus!$G$2:$G$501,$B18) | D18: =SUMIFS('Dépenses'!$F$2:$F$499,'Dépenses'!$H$2:$H$499,"<="&$B18,'Dépenses'!$G$2:$G$499,"Oui")*($B18<=DATE(YEAR(TODAY()),MONTH(TODAY()),1))+SUMIFS('Dépenses'!$F$2:$F$499,'Dépenses'!$H$2:$H$499,$B18,'Dépenses'!$G$2:$G$499,"<>Oui")+SUMIFS('Charges fixes'!$D$2:$D$100,'Charges fixes'!$E$2:$E$100,"<="&$B18)*($B18<=DATE(YEAR(TODAY()),MONTH(TODAY()),1)) | E18: =C18-D18 | F18: =IF(C18=0,0,E18/C18) | G18: =SUMIFS(Revenus!$E$2:$E$501,Revenus!$G$2:$G$501,$B18,Revenus!$F$2:$F$501,"Oui") | H18: =SUMIFS('Dépenses'!$F$2:$F$499,'Dépenses'!$H$2:$H$499,"<="&$B18,'Dépenses'!$G$2:$G$499,"Oui")*($B18<=DATE(YEAR(TODAY()),MONTH(TODAY()),1))+SUMIFS('Charges fixes'!$D$2:$D$100,'Charges fixes'!$E$2:$E$100,"<="&$B18)*($B18<=DATE(YEAR(TODAY()),MONTH(TODAY()),1))
B19: 46266 | C19: =SUMIFS(Revenus!$E$2:$E$501,Revenus!$G$2:$G$501,$B19) | D19: =SUMIFS('Dépenses'!$F$2:$F$499,'Dépenses'!$H$2:$H$499,"<="&$B19,'Dépenses'!$G$2:$G$499,"Oui")*($B19<=DATE(YEAR(TODAY()),MONTH(TODAY()),1))+SUMIFS('Dépenses'!$F$2:$F$499,'Dépenses'!$H$2:$H$499,$B19,'Dépenses'!$G$2:$G$499,"<>Oui")+SUMIFS('Charges fixes'!$D$2:$D$100,'Charges fixes'!$E$2:$E$100,"<="&$B19)*($B19<=DATE(YEAR(TODAY()),MONTH(TODAY()),1)) | E19: =C19-D19 | F19: =IF(C19=0,0,E19/C19) | G19: =SUMIFS(Revenus!$E$2:$E$501,Revenus!$G$2:$G$501,$B19,Revenus!$F$2:$F$501,"Oui") | H19: =SUMIFS('Dépenses'!$F$2:$F$499,'Dépenses'!$H$2:$H$499,"<="&$B19,'Dépenses'!$G$2:$G$499,"Oui")*($B19<=DATE(YEAR(TODAY()),MONTH(TODAY()),1))+SUMIFS('Charges fixes'!$D$2:$D$100,'Charges fixes'!$E$2:$E$100,"<="&$B19)*($B19<=DATE(YEAR(TODAY()),MONTH(TODAY()),1))
B20: 46296 | C20: =SUMIFS(Revenus!$E$2:$E$501,Revenus!$G$2:$G$501,$B20) | D20: =SUMIFS('Dépenses'!$F$2:$F$499,'Dépenses'!$H$2:$H$499,"<="&$B20,'Dépenses'!$G$2:$G$499,"Oui")*($B20<=DATE(YEAR(TODAY()),MONTH(TODAY()),1))+SUMIFS('Dépenses'!$F$2:$F$499,'Dépenses'!$H$2:$H$499,$B20,'Dépenses'!$G$2:$G$499,"<>Oui")+SUMIFS('Charges fixes'!$D$2:$D$100,'Charges fixes'!$E$2:$E$100,"<="&$B20)*($B20<=DATE(YEAR(TODAY()),MONTH(TODAY()),1)) | E20: =C20-D20 | F20: =IF(C20=0,0,E20/C20) | G20: =SUMIFS(Revenus!$E$2:$E$501,Revenus!$G$2:$G$501,$B20,Revenus!$F$2:$F$501,"Oui") | H20: =SUMIFS('Dépenses'!$F$2:$F$499,'Dépenses'!$H$2:$H$499,"<="&$B20,'Dépenses'!$G$2:$G$499,"Oui")*($B20<=DATE(YEAR(TODAY()),MONTH(TODAY()),1))+SUMIFS('Charges fixes'!$D$2:$D$100,'Charges fixes'!$E$2:$E$100,"<="&$B20)*($B20<=DATE(YEAR(TODAY()),MONTH(TODAY()),1))
B21: 46327 | C21: =SUMIFS(Revenus!$E$2:$E$501,Revenus!$G$2:$G$501,$B21) | D21: =SUMIFS('Dépenses'!$F$2:$F$499,'Dépenses'!$H$2:$H$499,"<="&$B21,'Dépenses'!$G$2:$G$499,"Oui")*($B21<=DATE(YEAR(TODAY()),MONTH(TODAY()),1))+SUMIFS('Dépenses'!$F$2:$F$499,'Dépenses'!$H$2:$H$499,$B21,'Dépenses'!$G$2:$G$499,"<>Oui")+SUMIFS('Charges fixes'!$D$2:$D$100,'Charges fixes'!$E$2:$E$100,"<="&$B21)*($B21<=DATE(YEAR(TODAY()),MONTH(TODAY()),1)) | E21: =C21-D21 | F21: =IF(C21=0,0,E21/C21) | G21: =SUMIFS(Revenus!$E$2:$E$501,Revenus!$G$2:$G$501,$B21,Revenus!$F$2:$F$501,"Oui") | H21: =SUMIFS('Dépenses'!$F$2:$F$499,'Dépenses'!$H$2:$H$499,"<="&$B21,'Dépenses'!$G$2:$G$499,"Oui")*($B21<=DATE(YEAR(TODAY()),MONTH(TODAY()),1))+SUMIFS('Charges fixes'!$D$2:$D$100,'Charges fixes'!$E$2:$E$100,"<="&$B21)*($B21<=DATE(YEAR(TODAY()),MONTH(TODAY()),1))
B22: 46357 | C22: =SUMIFS(Revenus!$E$2:$E$501,Revenus!$G$2:$G$501,$B22) | D22: =SUMIFS('Dépenses'!$F$2:$F$499,'Dépenses'!$H$2:$H$499,"<="&$B22,'Dépenses'!$G$2:$G$499,"Oui")*($B22<=DATE(YEAR(TODAY()),MONTH(TODAY()),1))+SUMIFS('Dépenses'!$F$2:$F$499,'Dépenses'!$H$2:$H$499,$B22,'Dépenses'!$G$2:$G$499,"<>Oui")+SUMIFS('Charges fixes'!$D$2:$D$100,'Charges fixes'!$E$2:$E$100,"<="&$B22)*($B22<=DATE(YEAR(TODAY()),MONTH(TODAY()),1)) | E22: =C22-D22 | F22: =IF(C22=0,0,E22/C22) | G22: =SUMIFS(Revenus!$E$2:$E$501,Revenus!$G$2:$G$501,$B22,Revenus!$F$2:$F$501,"Oui") | H22: =SUMIFS('Dépenses'!$F$2:$F$499,'Dépenses'!$H$2:$H$499,"<="&$B22,'Dépenses'!$G$2:$G$499,"Oui")*($B22<=DATE(YEAR(TODAY()),MONTH(TODAY()),1))+SUMIFS('Charges fixes'!$D$2:$D$100,'Charges fixes'!$E$2:$E$100,"<="&$B22)*($B22<=DATE(YEAR(TODAY()),MONTH(TODAY()),1))
B23: TOTAL | C23: =SUM(C11:C22) | D23: =SUM(D11:D22) | E23: =SUM(E11:E22) | F23: =IF(C23=0,0,E23/C23) | G23: =SUM(G11:G22) | H23: =SUM(H11:H22)
B25: Revenus par catégorie | F25: Dépenses par catégorie
B26: Catégorie | C26: Montant | D26: % du total | F26: Catégorie | G26: Montant | H26: % du total
B27: Téléprospection | C27: =SUMIF(Revenus!$C$2:$C$501,B27,Revenus!$E$2:$E$501) | D27: =IF($B$7=0,0,C27/$B$7) | F27: Salaires Madagascar | G27: {=SUMPRODUCT(('Dépenses'!$D$2:$D$499=F27)*('Dépenses'!$G$2:$G$499<>"Oui")*('Dépenses'!$F$2:$F$499))+SUMPRODUCT(('Dépenses'!$D$2:$D$499=F27)*('Dépenses'!$G$2:$G$499="Oui")*('Dépenses'!$F$2:$F$499)*IF('Dépenses'!$H$2:$H$499="",0,INT((YEAR(TODAY())-YEAR('Dépenses'!$H$2:$H$499))*12+MONTH(TODAY())-MONTH('Dépenses'!$H$2:$H$499)+1)))+SUMPRODUCT(('Charges fixes'!$B$2:$B$100=F27)*('Charges fixes'!$D$2:$D$100)*IF('Charges fixes'!$E$2:$E$100="",0,INT((YEAR(TODAY())-YEAR('Charges fixes'!$E$2:$E$100))*12+MONTH(TODAY())-MONTH('Charges fixes'!$E$2:$E$100)+1)))} | H27: =IF($D$7=0,0,G27/$D$7)
B28: Automation (N8N/Make) | C28: =SUMIF(Revenus!$C$2:$C$501,B28,Revenus!$E$2:$E$501) | D28: =IF($B$7=0,0,C28/$B$7) | F28: Outils SaaS | G28: {=SUMPRODUCT(('Dépenses'!$D$2:$D$499=F28)*('Dépenses'!$G$2:$G$499<>"Oui")*('Dépenses'!$F$2:$F$499))+SUMPRODUCT(('Dépenses'!$D$2:$D$499=F28)*('Dépenses'!$G$2:$G$499="Oui")*('Dépenses'!$F$2:$F$499)*IF('Dépenses'!$H$2:$H$499="",0,INT((YEAR(TODAY())-YEAR('Dépenses'!$H$2:$H$499))*12+MONTH(TODAY())-MONTH('Dépenses'!$H$2:$H$499)+1)))+SUMPRODUCT(('Charges fixes'!$B$2:$B$100=F28)*('Charges fixes'!$D$2:$D$100)*IF('Charges fixes'!$E$2:$E$100="",0,INT((YEAR(TODAY())-YEAR('Charges fixes'!$E$2:$E$100))*12+MONTH(TODAY())-MONTH('Charges fixes'!$E$2:$E$100)+1)))} | H28: =IF($D$7=0,0,G28/$D$7)
B29: Agent IA custom | C29: =SUMIF(Revenus!$C$2:$C$501,B29,Revenus!$E$2:$E$501) | D29: =IF($B$7=0,0,C29/$B$7) | F29: Marketing / Pub | G29: {=SUMPRODUCT(('Dépenses'!$D$2:$D$499=F29)*('Dépenses'!$G$2:$G$499<>"Oui")*('Dépenses'!$F$2:$F$499))+SUMPRODUCT(('Dépenses'!$D$2:$D$499=F29)*('Dépenses'!$G$2:$G$499="Oui")*('Dépenses'!$F$2:$F$499)*IF('Dépenses'!$H$2:$H$499="",0,INT((YEAR(TODAY())-YEAR('Dépenses'!$H$2:$H$499))*12+MONTH(TODAY())-MONTH('Dépenses'!$H$2:$H$499)+1)))+SUMPRODUCT(('Charges fixes'!$B$2:$B$100=F29)*('Charges fixes'!$D$2:$D$100)*IF('Charges fixes'!$E$2:$E$100="",0,INT((YEAR(TODAY())-YEAR('Charges fixes'!$E$2:$E$100))*12+MONTH(TODAY())-MONTH('Charges fixes'!$E$2:$E$100)+1)))} | H29: =IF($D$7=0,0,G29/$D$7)
B30: Abonnement Unimatos | C30: =SUMIF(Revenus!$C$2:$C$501,B30,Revenus!$E$2:$E$501) | D30: =IF($B$7=0,0,C30/$B$7) | F30: Comptable / Juridique | G30: {=SUMPRODUCT(('Dépenses'!$D$2:$D$499=F30)*('Dépenses'!$G$2:$G$499<>"Oui")*('Dépenses'!$F$2:$F$499))+SUMPRODUCT(('Dépenses'!$D$2:$D$499=F30)*('Dépenses'!$G$2:$G$499="Oui")*('Dépenses'!$F$2:$F$499)*IF('Dépenses'!$H$2:$H$499="",0,INT((YEAR(TODAY())-YEAR('Dépenses'!$H$2:$H$499))*12+MONTH(TODAY())-MONTH('Dépenses'!$H$2:$H$499)+1)))+SUMPRODUCT(('Charges fixes'!$B$2:$B$100=F30)*('Charges fixes'!$D$2:$D$100)*IF('Charges fixes'!$E$2:$E$100="",0,INT((YEAR(TODAY())-YEAR('Charges fixes'!$E$2:$E$100))*12+MONTH(TODAY())-MONTH('Charges fixes'!$E$2:$E$100)+1)))} | H30: =IF($D$7=0,0,G30/$D$7)
B31: Audit / Conseil | C31: =SUMIF(Revenus!$C$2:$C$501,B31,Revenus!$E$2:$E$501) | D31: =IF($B$7=0,0,C31/$B$7) | F31: Charges sociales (URSSAF) | G31: {=SUMPRODUCT(('Dépenses'!$D$2:$D$499=F31)*('Dépenses'!$G$2:$G$499<>"Oui")*('Dépenses'!$F$2:$F$499))+SUMPRODUCT(('Dépenses'!$D$2:$D$499=F31)*('Dépenses'!$G$2:$G$499="Oui")*('Dépenses'!$F$2:$F$499)*IF('Dépenses'!$H$2:$H$499="",0,INT((YEAR(TODAY())-YEAR('Dépenses'!$H$2:$H$499))*12+MONTH(TODAY())-MONTH('Dépenses'!$H$2:$H$499)+1)))+SUMPRODUCT(('Charges fixes'!$B$2:$B$100=F31)*('Charges fixes'!$D$2:$D$100)*IF('Charges fixes'!$E$2:$E$100="",0,INT((YEAR(TODAY())-YEAR('Charges fixes'!$E$2:$E$100))*12+MONTH(TODAY())-MONTH('Charges fixes'!$E$2:$E$100)+1)))} | H31: =IF($D$7=0,0,G31/$D$7)
B32: Setup / One-shot | C32: =SUMIF(Revenus!$C$2:$C$501,B32,Revenus!$E$2:$E$501) | D32: =IF($B$7=0,0,C32/$B$7) | F32: Frais bancaires | G32: {=SUMPRODUCT(('Dépenses'!$D$2:$D$499=F32)*('Dépenses'!$G$2:$G$499<>"Oui")*('Dépenses'!$F$2:$F$499))+SUMPRODUCT(('Dépenses'!$D$2:$D$499=F32)*('Dépenses'!$G$2:$G$499="Oui")*('Dépenses'!$F$2:$F$499)*IF('Dépenses'!$H$2:$H$499="",0,INT((YEAR(TODAY())-YEAR('Dépenses'!$H$2:$H$499))*12+MONTH(TODAY())-MONTH('Dépenses'!$H$2:$H$499)+1)))+SUMPRODUCT(('Charges fixes'!$B$2:$B$100=F32)*('Charges fixes'!$D$2:$D$100)*IF('Charges fixes'!$E$2:$E$100="",0,INT((YEAR(TODAY())-YEAR('Charges fixes'!$E$2:$E$100))*12+MONTH(TODAY())-MONTH('Charges fixes'!$E$2:$E$100)+1)))} | H32: =IF($D$7=0,0,G32/$D$7)
B33: Formation | C33: =SUMIF(Revenus!$C$2:$C$501,B33,Revenus!$E$2:$E$501) | D33: =IF($B$7=0,0,C33/$B$7) | F33: Sous-traitance | G33: {=SUMPRODUCT(('Dépenses'!$D$2:$D$499=F33)*('Dépenses'!$G$2:$G$499<>"Oui")*('Dépenses'!$F$2:$F$499))+SUMPRODUCT(('Dépenses'!$D$2:$D$499=F33)*('Dépenses'!$G$2:$G$499="Oui")*('Dépenses'!$F$2:$F$499)*IF('Dépenses'!$H$2:$H$499="",0,INT((YEAR(TODAY())-YEAR('Dépenses'!$H$2:$H$499))*12+MONTH(TODAY())-MONTH('Dépenses'!$H$2:$H$499)+1)))+SUMPRODUCT(('Charges fixes'!$B$2:$B$100=F33)*('Charges fixes'!$D$2:$D$100)*IF('Charges fixes'!$E$2:$E$100="",0,INT((YEAR(TODAY())-YEAR('Charges fixes'!$E$2:$E$100))*12+MONTH(TODAY())-MONTH('Charges fixes'!$E$2:$E$100)+1)))} | H33: =IF($D$7=0,0,G33/$D$7)
B34: Autre | C34: =SUMIF(Revenus!$C$2:$C$501,B34,Revenus!$E$2:$E$501) | D34: =IF($B$7=0,0,C34/$B$7) | F34: Matériel / Infra | G34: {=SUMPRODUCT(('Dépenses'!$D$2:$D$499=F34)*('Dépenses'!$G$2:$G$499<>"Oui")*('Dépenses'!$F$2:$F$499))+SUMPRODUCT(('Dépenses'!$D$2:$D$499=F34)*('Dépenses'!$G$2:$G$499="Oui")*('Dépenses'!$F$2:$F$499)*IF('Dépenses'!$H$2:$H$499="",0,INT((YEAR(TODAY())-YEAR('Dépenses'!$H$2:$H$499))*12+MONTH(TODAY())-MONTH('Dépenses'!$H$2:$H$499)+1)))+SUMPRODUCT(('Charges fixes'!$B$2:$B$100=F34)*('Charges fixes'!$D$2:$D$100)*IF('Charges fixes'!$E$2:$E$100="",0,INT((YEAR(TODAY())-YEAR('Charges fixes'!$E$2:$E$100))*12+MONTH(TODAY())-MONTH('Charges fixes'!$E$2:$E$100)+1)))} | H34: =IF($D$7=0,0,G34/$D$7)
F35: Déplacements | G35: {=SUMPRODUCT(('Dépenses'!$D$2:$D$499=F35)*('Dépenses'!$G$2:$G$499<>"Oui")*('Dépenses'!$F$2:$F$499))+SUMPRODUCT(('Dépenses'!$D$2:$D$499=F35)*('Dépenses'!$G$2:$G$499="Oui")*('Dépenses'!$F$2:$F$499)*IF('Dépenses'!$H$2:$H$499="",0,INT((YEAR(TODAY())-YEAR('Dépenses'!$H$2:$H$499))*12+MONTH(TODAY())-MONTH('Dépenses'!$H$2:$H$499)+1)))+SUMPRODUCT(('Charges fixes'!$B$2:$B$100=F35)*('Charges fixes'!$D$2:$D$100)*IF('Charges fixes'!$E$2:$E$100="",0,INT((YEAR(TODAY())-YEAR('Charges fixes'!$E$2:$E$100))*12+MONTH(TODAY())-MONTH('Charges fixes'!$E$2:$E$100)+1)))} | H35: =IF($D$7=0,0,G35/$D$7)
F36: Autre | G36: {=SUMPRODUCT(('Dépenses'!$D$2:$D$499=F36)*('Dépenses'!$G$2:$G$499<>"Oui")*('Dépenses'!$F$2:$F$499))+SUMPRODUCT(('Dépenses'!$D$2:$D$499=F36)*('Dépenses'!$G$2:$G$499="Oui")*('Dépenses'!$F$2:$F$499)*IF('Dépenses'!$H$2:$H$499="",0,INT((YEAR(TODAY())-YEAR('Dépenses'!$H$2:$H$499))*12+MONTH(TODAY())-MONTH('Dépenses'!$H$2:$H$499)+1)))+SUMPRODUCT(('Charges fixes'!$B$2:$B$100=F36)*('Charges fixes'!$D$2:$D$100)*IF('Charges fixes'!$E$2:$E$100="",0,INT((YEAR(TODAY())-YEAR('Charges fixes'!$E$2:$E$100))*12+MONTH(TODAY())-MONTH('Charges fixes'!$E$2:$E$100)+1)))} | H36: =IF($D$7=0,0,G36/$D$7)
B38: Rentabilité par client
B39: Client | C39: CA HT | D39: Charges | E39: Marge | F39: Marge %
B40: Hassan | C40: {=SUMPRODUCT((Revenus!$B$2:$B$501=B40)*(Revenus!$F$2:$F$501<>"Oui")*(Revenus!$E$2:$E$501))+SUMPRODUCT((Revenus!$B$2:$B$501=B40)*(Revenus!$F$2:$F$501="Oui")*(Revenus!$E$2:$E$501)*IF(Revenus!$G$2:$G$501="",0,INT((YEAR(TODAY())-YEAR(Revenus!$G$2:$G$501))*12+MONTH(TODAY())-MONTH(Revenus!$G$2:$G$501)+1)))} | D40: {=SUMPRODUCT(('Dépenses'!$B$2:$B$499=B40)*('Dépenses'!$G$2:$G$499<>"Oui")*('Dépenses'!$F$2:$F$499))+SUMPRODUCT(('Dépenses'!$B$2:$B$499=B40)*('Dépenses'!$G$2:$G$499="Oui")*('Dépenses'!$F$2:$F$499)*IF('Dépenses'!$H$2:$H$499="",0,INT((YEAR(TODAY())-YEAR('Dépenses'!$H$2:$H$499))*12+MONTH(TODAY())-MONTH('Dépenses'!$H$2:$H$499)+1)))+IF(B40="Général",0,SUMPRODUCT(('Charges fixes'!$D$2:$D$100)*IF('Charges fixes'!$E$2:$E$100="",0,INT((YEAR(TODAY())-YEAR('Charges fixes'!$E$2:$E$100))*12+MONTH(TODAY())-MONTH('Charges fixes'!$E$2:$E$100)+1)))/ROWS(UNIQUE(_xlws.FILTER(Revenus!$B$2:$B$501,Revenus!$B$2:$B$501<>""))))} | E40: =C40-D40 | F40: =IF(C40=0,0,E40/C40)
B41: Jennifer DA COSTA | C41: {=SUMPRODUCT((Revenus!$B$2:$B$501=B41)*(Revenus!$F$2:$F$501<>"Oui")*(Revenus!$E$2:$E$501))+SUMPRODUCT((Revenus!$B$2:$B$501=B41)*(Revenus!$F$2:$F$501="Oui")*(Revenus!$E$2:$E$501)*IF(Revenus!$G$2:$G$501="",0,INT((YEAR(TODAY())-YEAR(Revenus!$G$2:$G$501))*12+MONTH(TODAY())-MONTH(Revenus!$G$2:$G$501)+1)))} | D41: {=SUMPRODUCT(('Dépenses'!$B$2:$B$499=B41)*('Dépenses'!$G$2:$G$499<>"Oui")*('Dépenses'!$F$2:$F$499))+SUMPRODUCT(('Dépenses'!$B$2:$B$499=B41)*('Dépenses'!$G$2:$G$499="Oui")*('Dépenses'!$F$2:$F$499)*IF('Dépenses'!$H$2:$H$499="",0,INT((YEAR(TODAY())-YEAR('Dépenses'!$H$2:$H$499))*12+MONTH(TODAY())-MONTH('Dépenses'!$H$2:$H$499)+1)))+IF(B41="Général",0,SUMPRODUCT(('Charges fixes'!$D$2:$D$100)*IF('Charges fixes'!$E$2:$E$100="",0,INT((YEAR(TODAY())-YEAR('Charges fixes'!$E$2:$E$100))*12+MONTH(TODAY())-MONTH('Charges fixes'!$E$2:$E$100)+1)))/ROWS(UNIQUE(_xlws.FILTER(Revenus!$B$2:$B$501,Revenus!$B$2:$B$501<>""))))} | E41: =C41-D41 | F41: =IF(C41=0,0,E41/C41)
B42: Louis | C42: {=SUMPRODUCT((Revenus!$B$2:$B$501=B42)*(Revenus!$F$2:$F$501<>"Oui")*(Revenus!$E$2:$E$501))+SUMPRODUCT((Revenus!$B$2:$B$501=B42)*(Revenus!$F$2:$F$501="Oui")*(Revenus!$E$2:$E$501)*IF(Revenus!$G$2:$G$501="",0,INT((YEAR(TODAY())-YEAR(Revenus!$G$2:$G$501))*12+MONTH(TODAY())-MONTH(Revenus!$G$2:$G$501)+1)))} | D42: {=SUMPRODUCT(('Dépenses'!$B$2:$B$499=B42)*('Dépenses'!$G$2:$G$499<>"Oui")*('Dépenses'!$F$2:$F$499))+SUMPRODUCT(('Dépenses'!$B$2:$B$499=B42)*('Dépenses'!$G$2:$G$499="Oui")*('Dépenses'!$F$2:$F$499)*IF('Dépenses'!$H$2:$H$499="",0,INT((YEAR(TODAY())-YEAR('Dépenses'!$H$2:$H$499))*12+MONTH(TODAY())-MONTH('Dépenses'!$H$2:$H$499)+1)))+IF(B42="Général",0,SUMPRODUCT(('Charges fixes'!$D$2:$D$100)*IF('Charges fixes'!$E$2:$E$100="",0,INT((YEAR(TODAY())-YEAR('Charges fixes'!$E$2:$E$100))*12+MONTH(TODAY())-MONTH('Charges fixes'!$E$2:$E$100)+1)))/ROWS(UNIQUE(_xlws.FILTER(Revenus!$B$2:$B$501,Revenus!$B$2:$B$501<>""))))} | E42: =C42-D42 | F42: =IF(C42=0,0,E42/C42)
B43: Général | C43: {=SUMPRODUCT((Revenus!$B$2:$B$501=B43)*(Revenus!$F$2:$F$501<>"Oui")*(Revenus!$E$2:$E$501))+SUMPRODUCT((Revenus!$B$2:$B$501=B43)*(Revenus!$F$2:$F$501="Oui")*(Revenus!$E$2:$E$501)*IF(Revenus!$G$2:$G$501="",0,INT((YEAR(TODAY())-YEAR(Revenus!$G$2:$G$501))*12+MONTH(TODAY())-MONTH(Revenus!$G$2:$G$501)+1)))} | D43: {=SUMPRODUCT(('Dépenses'!$B$2:$B$499=B43)*('Dépenses'!$G$2:$G$499<>"Oui")*('Dépenses'!$F$2:$F$499))+SUMPRODUCT(('Dépenses'!$B$2:$B$499=B43)*('Dépenses'!$G$2:$G$499="Oui")*('Dépenses'!$F$2:$F$499)*IF('Dépenses'!$H$2:$H$499="",0,INT((YEAR(TODAY())-YEAR('Dépenses'!$H$2:$H$499))*12+MONTH(TODAY())-MONTH('Dépenses'!$H$2:$H$499)+1)))+IF(B43="Général",0,SUMPRODUCT(('Charges fixes'!$D$2:$D$100)*IF('Charges fixes'!$E$2:$E$100="",0,INT((YEAR(TODAY())-YEAR('Charges fixes'!$E$2:$E$100))*12+MONTH(TODAY())-MONTH('Charges fixes'!$E$2:$E$100)+1)))/ROWS(UNIQUE(_xlws.FILTER(Revenus!$B$2:$B$501,Revenus!$B$2:$B$501<>""))))} | E43: =C43-D43 | F43: =IF(C43=0,0,E43/C43)
B44: TOTAL | C44: =SUM(C40:C43) | D44: =SUM(D40:D43) | E44: =SUM(E40:E43) | F44: =IF(C44=0,0,E44/C44)
B51: Légende — couleur du texte
B52: Bleu | C52: Valeur saisie manuellement
...

Sheet Revenus
A1: Date | B1: Client | C1: Catégorie | D1: Description | E1: Montant HT (€) | F1: Récurrent | G1: Mois | H1: Notes
A2: 46104 | B2: Hassan | C2: Abonnement Unimatos | D2: Abonnement 6 mois Unimatos | E2: 450 | F2: Non | G2: =IF(A2="","",DATE(YEAR(A2),MONTH(A2),1))
A3: 46130 | B3: Jennifer DA COSTA | C3: Setup / One-shot | D3: ADV / mensuel | E3: 600 | F3: Oui | G3: 46113
A4: 46134 | B4: Louis | C4: Setup / One-shot | D4: TP / Mensuel | E4: 1500 | F4: Oui | G4: 46113
A5: 46136 | B5: PATTOM | C5: Agent IA custom | D5: Auto Linkedin, 2 TP, scalead | E5: 2400 | F5: Oui | G5: =IF(A5="","",DATE(YEAR(A5),MONTH(A5),1))
A6: 46151 | B6: Nicolas | C6: Setup / One-shot | D6: TP / Mensuel | E6: 750 | F6: Non | G6: =IF(A6="","",DATE(YEAR(A6),MONTH(A6),1))
A7: 46153 | B7: SPOM | C7: Setup / One-shot | D7: TP / Mensuel | E7: 750 | F7: Non | G7: =IF(A7="","",DATE(YEAR(A7),MONTH(A7),1))
A8: 46179 | B8: Jennifer DA COSTA | C8: Setup / One-shot | D8: ADV / mensuel | E8: 600 | F8: Oui | G8: =IF(A8="","",DATE(YEAR(A8),MONTH(A8),1))
A9: 46232 | B9: Jennifer DA COSTA | C9: Setup / One-shot | D9: ADV / mensuel | E9: 600 | F9: Oui | G9: =IF(A9="","",DATE(YEAR(A9),MONTH(A9),1)) | H9: Facture 2026-002 (Jonction)
A10: 46203 | B10: PATTOM | C10: Téléprospection | D10: 2 TP (Jimmy & Safidy) | E10: 1400 | F10: Oui | G10: =IF(A10="","",DATE(YEAR(A10),MONTH(A10),1)) | H10: Facture 2026-003 (Jonction)
G11: =IF(A11="","",DATE(YEAR(A11),MONTH(A11),1))
G12: =IF(A12="","",DATE(YEAR(A12),MONTH(A12),1))
G13: =IF(A13="","",DATE(YEAR(A13),MONTH(A13),1))
G14: =IF(A14="","",DATE(YEAR(A14),MONTH(A14),1))
G15: =IF(A15="","",DATE(YEAR(A15),MONTH(A15),1))
G16: =IF(A16="","",DATE(YEAR(A16),MONTH(A16),1))
G17: =IF(A17="","",DATE(YEAR(A17),MONTH(A17),1))
G18: =IF(A18="","",DATE(YEAR(A18),MONTH(A18),1))
G19: =IF(A19="","",DATE(YEAR(A19),MONTH(A19),1))
G20: =IF(A20="","",DATE(YEAR(A20),MONTH(A20),1))
G21: =IF(A21="","",DATE(YEAR(A21),MONTH(A21),1))
G22: =IF(A22="","",DATE(YEAR(A22),MONTH(A22),1))
... G501: =IF(A501="","",DATE(YEAR(A501),MONTH(A501),1))

Sheet Dépenses
A1: Date | B1: Client | C1: Fournisseur | D1: Catégorie | E1: Description | F1: Montant HT (€) | G1: Récurrent | H1: Mois d'entrée en compte | I1: Notes
A2: 46113 | B2: Jennifer DA COSTA | C2: Équipe Madagascar | D2: Salaires Madagascar | E2: Salaire Jimmy | F2: 400 | G2: Oui | H2: 46113 | I2: Coût direct téléprospection
A3: 46032 | B3: Jennifer DA COSTA | C3: SLACK | D3: Outils SaaS | E3: Plan Pro | F3: 10 | G3: Oui | H3: 46113
A4: 46032 | B4: Jennifer DA COSTA | C4: Allô | D4: Outils SaaS | E4: admin | F4: 84 | G4: Oui | H4: 46113
A5: 46113 | B5: Général | C5: Equipe Madagascar | D5: Salaires Madagascar | E5: Salaire Elicia | F5: 40 | G5: Non | H5: =IF(A5="","",DATE(YEAR(A5),MONTH(A5),1))
A6: 46134 | B6: Louis | D6: Salaire Thiago | E6: Salaire Thiago | F6: 450 | G6: Oui | H6: 46113
A7: 46134 | B7: Général | D7: Outils SaaS | E7: Claude API | F7: 20 | G7: Non | H7: 46082
A8: 46134 | B8: Général | D8: designer | E8: prestataire me designer | F8: 280 | G8: Non | H8: 46082
A9: 46134 | B9: Louis | D9: Salaires Madagascar | E9: Salaire futur TP pour Louis | F9: 400 | G9: Oui | H9: 46113
A10: 46134 | B10: Louis | D10: frais stripe | E10: commission stripe | F10: 30 | G10: Oui | H10: =IF(A10="","",DATE(YEAR(A10),MONTH(A10),1)) | I10: payé par Thiago
A11: 46174 | B11: Pattom | C11: Equipe madagascar | D11: Salaires Madagascar | E11: Salaire futur TP pour Pattom | F11: 400 | G11: Oui | H11: =IF(A11="","",DATE(YEAR(A11),MONTH(A11),1)) | I11: 1er TP
A12: 46174 | B12: Pattom | C12: Equipe madagascar | D12: Salaires Madagascar | E12: Salaire futur TP pour Pattom | F12: 400 | G12: Oui | H12: =IF(A12="","",DATE(YEAR(A12),MONTH(A12),1)) | I12: 2eme TP
A13: 46136 | B13: Pattom | C13: slack | D13: Outils SaaS | E13: siège | F13: 20 | G13: Oui | H13: =IF(A13="","",DATE(YEAR(A13),MONTH(A13),1)) | I13: a confirmer
A14: 46136 | B14: Pattom | C14: automatisation Linkedin | D14: Outils SaaS | H14: =IF(A14="","",DATE(YEAR(A14),MONTH(A14),1))
A15: 46136 | B15: Pattom | C15: NDF | D15: Frais bancaires | E15: repas midi | F15: 130 | G15: non | H15: =IF(A15="","",DATE(YEAR(A15),MONTH(A15),1)) | I15: invitation pattom
A16: 46146 | B16: Louis | C16: Allô | D16: Outils SaaS | E16: siege Anthony | F16: 30 | G16: non | H16: =IF(A16="","",DATE(YEAR(A16),MONTH(A16),1))
A17: 46154 | C17: Allô | D17: Outils SaaS | E17: siege Anthony | F17: 35 | G17: non | H17: =IF(A17="","",DATE(YEAR(A17),MONTH(A17),1)) | I17: Angélica
A18: 46154 | B18: Scalyx | C18: Equipe madagascar | D18: Salaires Madagascar | E18: 1 salaire 1/2 temps | F18: 200 | H18: =IF(A18="","",DATE(YEAR(A18),MONTH(A18),1)) | I18: Angélica
A19: 46154 | B19: SPOM | C19: Equipe madagascar | D19: Salaires Madagascar | E19: 1 salaire 1/2 temps | F19: 200 | H19: =IF(A19="","",DATE(YEAR(A19),MONTH(A19),1)) | I19: Angélica
H21: =IF(A21="","",DATE(YEAR(A21),MONTH(A21),1))
H22: =IF(A22="","",DATE(YEAR(A22),MONTH(A22),1))
H23: =IF(A23="","",DATE(YEAR(A23),MONTH(A23),1))
H24: =IF(A24="","",DATE(YEAR(A24),MONTH(A24),1))
H25: =IF(A25="","",DATE(YEAR(A25),MONTH(A25),1))
H26: =IF(A26="","",DATE(YEAR(A26),MONTH(A26),1))
H27: =IF(A27="","",DATE(YEAR(A27),MONTH(A27),1))
H28: =IF(A28="","",DATE(YEAR(A28),MONTH(A28),1))
H29: =IF(A29="","",DATE(YEAR(A29),MONTH(A29),1))
H30: =IF(A30="","",DATE(YEAR(A30),MONTH(A30),1))
H31: =IF(A31="","",DATE(YEAR(A31),MONTH(A31),1))
H32: =IF(A32="","",DATE(YEAR(A32),MONTH(A32),1))
... H499: =IF(A499="","",DATE(YEAR(A499),MONTH(A499),1))

Sheet Charges fixes
A1: Fournisseur | B1: Catégorie | C1: Description | D1: Montant HT (€) | E1: Mois d'entrée en compte
A2: Anthropic | B2: Outils SaaS | C2: Claude API | D2: 100 | E2: 46113
A3: Hostinguer VPS | B3: Outils SaaS | C3: Plan Pro | D3: 25 | E3: 46113

Sheet Paramètres
A1: Catégories Revenus | C1: Catégories Dépenses | E1: Astuce
A2: Téléprospection | C2: Salaires Madagascar | E2: Tu peux ajouter / renommer les catégories.
A3: Automation (N8N/Make) | C3: Outils SaaS | E3: Elles apparaîtront dans les menus déroulants
A4: Agent IA custom | C4: Marketing / Pub | E4: des onglets Revenus et Dépenses.
A5: Abonnement Unimatos | C5: Comptable / Juridique
A6: Audit / Conseil | C6: Charges sociales (URSSAF)
A7: Setup / One-shot | C7: Frais bancaires
A8: Formation | C8: Sous-traitance
A9: Autre | C9: Matériel / Infra
C10: Déplacements
C11: Autre
